2024-12-14 11:25:21,075 - __main__ - INFO - Initialized Hugging Face Inference Client with model: meta-llama/Llama-3.2-1B
2024-12-14 11:25:21,077 - werkzeug - INFO - [31m[1mWARNING: This is a development server. Do not use it in a production deployment. Use a production WSGI server instead.[0m
 * Running on all addresses (0.0.0.0)
 * Running on http://127.0.0.1:5000
 * Running on http://192.168.126.13:5000
2024-12-14 11:25:21,077 - werkzeug - INFO - [33mPress CTRL+C to quit[0m
2024-12-14 11:25:25,416 - __main__ - INFO - User input: please predect the churn for customer A. the data is gender male, Senior_Citizen no, Is_Married yes, Dependents yes, tenure 10, Dual yes, Contract month-to-month, Paperless_Billing yes, Payment_Method electronic check, Monthly_Charges 100, Online_Security yes, Online_Backup yes, Device_Protection no, Streaming_TV yes, Streaming_Movies no, Internet_Service yes, Tech_Support yes

2024-12-14 11:25:25,425 - __main__ - INFO - Input successfully parsed and converted to dataframe.
2024-12-14 11:25:25,425 - __main__ - ERROR - Error during response generation: name 'parsed_input' is not defined
2024-12-14 11:25:25,426 - __main__ - ERROR - Traceback (most recent call last):
  File "ll.py", line 289, in generate_response
    missing_fields = self.prompt_engineer.validate_context(parsed_input, self.required_fields)
NameError: name 'parsed_input' is not defined

2024-12-14 11:25:25,427 - ll - ERROR - Exception on /api/v1/response [POST]
Traceback (most recent call last):
  File "ll.py", line 289, in generate_response
    missing_fields = self.prompt_engineer.validate_context(parsed_input, self.required_fields)
NameError: name 'parsed_input' is not defined

During handling of the above exception, another exception occurred:

Traceback (most recent call last):
  File "/home/mazen/Desktop/new/etisalatEnv/lib/python3.8/site-packages/flask/app.py", line 1473, in wsgi_app
    response = self.full_dispatch_request()
  File "/home/mazen/Desktop/new/etisalatEnv/lib/python3.8/site-packages/flask/app.py", line 882, in full_dispatch_request
    rv = self.handle_user_exception(e)
  File "/home/mazen/Desktop/new/etisalatEnv/lib/python3.8/site-packages/flask/app.py", line 880, in full_dispatch_request
    rv = self.dispatch_request()
  File "/home/mazen/Desktop/new/etisalatEnv/lib/python3.8/site-packages/flask/app.py", line 865, in dispatch_request
    return self.ensure_sync(self.view_functions[rule.endpoint])(**view_args)  # type: ignore[no-any-return]
  File "ll.py", line 339, in getResponse
    response = chatbot.generate_response(user_input)
  File "ll.py", line 307, in generate_response
    raise RuntimeError(f"Could not generate response: {e}")
RuntimeError: Could not generate response: name 'parsed_input' is not defined
2024-12-14 11:25:25,431 - werkzeug - INFO - 192.168.126.25 - - [14/Dec/2024 11:25:25] "[35m[1mPOST /api/v1/response HTTP/1.1[0m" 500 -
2024-12-14 11:25:30,701 - __main__ - INFO - User input: please predect the churn for customer A. the data is gender male, Senior_Citizen no, Is_Married yes, Dependents yes, tenure 10, Dual yes, Contract month-to-month, Paperless_Billing yes, Payment_Method electronic check, Monthly_Charges 100, Online_Security yes, Online_Backup yes, Device_Protection no, Streaming_TV yes, Streaming_Movies no, Internet_Service yes, Tech_Support yes

2024-12-14 11:25:30,713 - __main__ - INFO - Input successfully parsed and converted to dataframe.
2024-12-14 11:25:30,713 - __main__ - ERROR - Error during response generation: name 'parsed_input' is not defined
2024-12-14 11:25:30,714 - __main__ - ERROR - Traceback (most recent call last):
  File "ll.py", line 289, in generate_response
    missing_fields = self.prompt_engineer.validate_context(parsed_input, self.required_fields)
NameError: name 'parsed_input' is not defined

2024-12-14 11:25:30,714 - ll - ERROR - Exception on /api/v1/response [POST]
Traceback (most recent call last):
  File "ll.py", line 289, in generate_response
    missing_fields = self.prompt_engineer.validate_context(parsed_input, self.required_fields)
NameError: name 'parsed_input' is not defined

During handling of the above exception, another exception occurred:

Traceback (most recent call last):
  File "/home/mazen/Desktop/new/etisalatEnv/lib/python3.8/site-packages/flask/app.py", line 1473, in wsgi_app
    response = self.full_dispatch_request()
  File "/home/mazen/Desktop/new/etisalatEnv/lib/python3.8/site-packages/flask/app.py", line 882, in full_dispatch_request
    rv = self.handle_user_exception(e)
  File "/home/mazen/Desktop/new/etisalatEnv/lib/python3.8/site-packages/flask/app.py", line 880, in full_dispatch_request
    rv = self.dispatch_request()
  File "/home/mazen/Desktop/new/etisalatEnv/lib/python3.8/site-packages/flask/app.py", line 865, in dispatch_request
    return self.ensure_sync(self.view_functions[rule.endpoint])(**view_args)  # type: ignore[no-any-return]
  File "ll.py", line 339, in getResponse
    response = chatbot.generate_response(user_input)
  File "ll.py", line 307, in generate_response
    raise RuntimeError(f"Could not generate response: {e}")
RuntimeError: Could not generate response: name 'parsed_input' is not defined
2024-12-14 11:25:30,716 - werkzeug - INFO - 192.168.126.25 - - [14/Dec/2024 11:25:30] "[35m[1mPOST /api/v1/response HTTP/1.1[0m" 500 -
